<?xml version="1.0"?>
<robot  name="gofa5_arm" >
 <link  name="world" />
 <joint  type="fixed"  name="world_gofa5_arm_joint" >
  <origin  rpy="0 0 0"  xyz="0 0 0" />
  <parent  link="world" />
  <child  link="gofa5_arm_link_0" />
 </joint>
 <link  name="gofa5_arm_link_0" >
  <inertial >
   <origin  rpy="0.0 0.0 0.0"  xyz="0.0 0.0 0.0" />
   <mass  value="2.0" />
   <inertia  ixz="0"  ixx="0"  izz="0"  iyz="0"  iyy="0"  ixy="0" />
  </inertial>
  <visual >
   <origin  xyz="0.0 0.0 0.0" />
  </visual>
  <collision >
   <origin  xyz="0.0 0.0 0.0" />
  </collision>
 </link>
 <joint  type="revolute"  name="gofa5_arm_joint_1" >
  <parent  link="gofa5_arm_link_0" />
  <child  link="gofa5_arm_link_1" />
  <origin  rpy="0.0 -0.0 0.0"  xyz="0.0 0.0 0.1855" />
  <axis  xyz="0 0 1" />
  <limit  velocity="10"  lower="-3.141592653589793"  effort="300"  upper="3.141592653589793" />
 </joint>
 <link  name="gofa5_arm_link_1" >
  <inertial >
   <origin  rpy="0.0 0.0 0.0"  xyz="0.0 0.0 0.0" />
   <mass  value="1.95" />
   <inertia  ixz="0"  ixx="0"  izz="0"  iyz="0"  iyy="0"  ixy="0" />
  </inertial>
  <visual >
   <origin  xyz="0.0 -0.02 0.0" />
  </visual>
  <collision >
   <origin  xyz="0.0 -0.02 0.0" />
  </collision>
 </link>
 <joint  type="revolute"  name="gofa5_arm_joint_2" >
  <parent  link="gofa5_arm_link_1" />
  <child  link="gofa5_arm_link_2" />
  <origin  rpy="1.5707963267948966 0.0 3.141592653589793"  xyz="0.0 -0.085 0.0765" />
  <axis  xyz="0 0 1" />
  <limit  velocity="10"  lower="-3.141592653589793"  effort="300"  upper="3.141592653589793" />
 </joint>
 <link  name="gofa5_arm_link_2" >
  <inertial >
   <origin  rpy="0.0 0.0 0.0"  xyz="0.0 0.0 0.0" />
   <mass  value="3.42" />
   <inertia  ixz="0"  ixx="0"  izz="0"  iyz="0"  iyy="0"  ixy="0" />
  </inertial>
  <visual >
   <origin  xyz="0.13 0.0 0.1157" />
  </visual>
  <collision >
   <origin  xyz="0.13 0.0 0.1157" />
  </collision>
 </link>
 <joint  type="revolute"  name="gofa5_arm_joint_3" >
  <parent  link="gofa5_arm_link_2" />
  <child  link="gofa5_arm_link_3" />
  <origin  rpy="0.0 0.0 0.0"  xyz="0.0 0.444 0.0" />
  <axis  xyz="0 0 1" />
  <limit  velocity="10"  lower="-3.141592653589793"  effort="300"  upper="3.141592653589793" />
 </joint>
 <link  name="gofa5_arm_link_3" >
  <inertial >
   <origin  rpy="0.0 0.0 0.0"  xyz="0.0 0.0 0.0" />
   <mass  value="1.437" />
   <inertia  ixz="0"  ixx="0"  izz="0"  iyz="0"  iyy="0"  ixy="0" />
  </inertial>
  <visual >
   <origin  xyz="0.05 0.0 0.0238" />
  </visual>
  <collision >
   <origin  xyz="0.05 0.0 0.0238" />
  </collision>
 </link>
 <joint  type="revolute"  name="gofa5_arm_joint_4" >
  <parent  link="gofa5_arm_link_3" />
  <child  link="gofa5_arm_link_4" />
  <origin  rpy="0.0 -1.5707963267948966 0.0"  xyz="-0.096 0.11 0.085" />
  <axis  xyz="0 0 1" />
  <limit  velocity="10"  lower="-3.141592653589793"  effort="300"  upper="3.141592653589793" />
 </joint>
 <link  name="gofa5_arm_link_4" >
  <inertial >
   <origin  rpy="0.0 0.0 0.0"  xyz="0.0 0.0 0.0" />
   <mass  value="0.871" />
   <inertia  ixz="0"  ixx="0"  izz="0"  iyz="0"  iyy="0"  ixy="0" />
  </inertial>
  <visual >
   <origin  xyz="0.0 0.0 0.01" />
  </visual>
  <collision >
   <origin  xyz="0.0 0.0 0.01" />
  </collision>
 </link>
 <joint  type="revolute"  name="gofa5_arm_joint_5" >
  <parent  link="gofa5_arm_link_4" />
  <child  link="gofa5_arm_link_5" />
  <origin  rpy="3.141592653589793 -1.5707963267948966 0.0"  xyz="0.0755 0.0 0.373" />
  <axis  xyz="0 0 1" />
  <limit  velocity="10"  lower="-3.141592653589793"  effort="300"  upper="3.141592653589793" />
 </joint>
 <link  name="gofa5_arm_link_5" >
  <inertial >
   <origin  rpy="0.0 0.0 0.0"  xyz="0.0 0.0 0.0" />
   <mass  value="0.8" />
   <inertia  ixz="0"  ixx="0"  izz="0"  iyz="0"  iyy="0"  ixy="0" />
  </inertial>
  <visual >
   <origin  xyz="0.0 0.0 0.01" />
  </visual>
  <collision >
   <origin  xyz="0.0 0.0 0.01" />
  </collision>
 </link>
 <joint  type="revolute"  name="gofa5_arm_joint_6" >
  <parent  link="gofa5_arm_link_5" />
  <child  link="gofa5_arm_link_6" />
  <origin  rpy="-1.5707963267948966 0.0 -1.5707963267948966"  xyz="0.101 -0.08 -0.0745" />
  <axis  xyz="0 0 1" />
  <limit  velocity="10"  lower="-3.141592653589793"  effort="300"  upper="3.141592653589793" />
 </joint>
 <link  name="gofa5_arm_link_6" >
  <inertial >
   <origin  rpy="0.0 0.0 0.0"  xyz="0.0 0.0 0.0" />
   <mass  value="0.8" />
   <inertia  ixz="0"  ixx="0"  izz="0"  iyz="0"  iyy="0"  ixy="0" />
  </inertial>
  <visual >
   <origin  xyz="0.0 0.0 0.0" />
  </visual>
  <collision >
   <origin  xyz="0.0 0.0 0.0" />
  </collision>
 </link>
</robot>
